<?xml version="1.0" encoding="utf-8"?>
<!-- =================================================================================== -->
<!-- |    This document was autogenerated by xacro from robot_environment.xacro        | -->
<!-- |    EDITING THIS FILE BY HAND IS NOT RECOMMENDED                                 | -->
<!-- =================================================================================== -->
<robot name="armrobot">
  <gazebo>
    <plugin filename="libgazebo_ros_control.so" name="gazebo_ros_control">
    </plugin>
  </gazebo>
  <link name="world"/>
  <joint name="world_joint" type="fixed">
    <origin rpy="0 0 0" xyz="0 0 0"/>
    <parent link="world"/>
    <child link="base_model"/>
  </joint>
  <!-- Base Model -->
  <link name="base_model">
    <inertial>
      <origin rpy="0 0 0" xyz="2e-06 0 0.019926"/>
      <mass value="1000"/>
      <inertia ixx="4.81154771451" ixy="0" ixz="0" iyy="4.81154771451" iyz="0" izz="9.62309542903"/>
    </inertial>
    <collision>
      <geometry>
        <mesh filename="package://robot_desc/models/BaseModel2.dae"/>
      </geometry>
    </collision>
    <visual>
      <geometry>
        <mesh filename="package://robot_desc/models/BaseModel2.dae"/>
      </geometry>
    </visual>
  </link>
  <gazebo reference="base_model">
    <material>Gazebo/DarkGrey</material>
    <selfCollide>true</selfCollide>
  </gazebo>
  <!-- Arm Construct -->
  <!-- 2 Adapter -->
  <link name="adapter_1_1">
    <inertial>
      <origin rpy="0 0 0" xyz="0 -0.003725 0.003727"/>
      <mass value="10"/>
      <inertia ixx="0.0172860847018" ixy="0" ixz="0" iyy="0.0172860847018" iyz="0" izz="0.0172860847018"/>
    </inertial>
    <collision name="adapter_1_1_collision">
      <geometry>
        <mesh filename="package://robot_desc/models/FirstLink.dae"/>
      </geometry>
    </collision>
    <visual>
      <geometry>
        <mesh filename="package://robot_desc/models/FirstLink.dae"/>
      </geometry>
    </visual>
  </link>
  <gazebo reference="adapter_1_1">
    <material>Gazebo/FlatBlack</material>
    <selfCollide>true</selfCollide>
  </gazebo>
  <!-- Contact Sensor -->
  <gazebo reference="adapter_1_1">
    <sensor name="adapter_1_1_contact_sensor" type="contact">
      <always_on>true</always_on>
      <contact>
        <collision>adapter_1_1_collision_collision</collision>
      </contact>
      <plugin filename="libgazebo_ros_bumper.so" name="adapter_1_1_plugin">
        <bumperTopicName>adapter_1_1_contact</bumperTopicName>
        <frameName>adapter_1_1</frameName>
      </plugin>
    </sensor>
  </gazebo>
  <link name="adapter_1_2">
    <inertial>
      <origin rpy="0 0 0" xyz="0 -0.003725 0.003727"/>
      <mass value="10"/>
      <inertia ixx="0.0172860847018" ixy="0" ixz="0" iyy="0.0172860847018" iyz="0" izz="0.0172860847018"/>
    </inertial>
    <collision name="adapter_1_2_collision">
      <geometry>
        <mesh filename="package://robot_desc/models/FirstLink.dae"/>
      </geometry>
    </collision>
    <visual>
      <geometry>
        <mesh filename="package://robot_desc/models/FirstLink.dae"/>
      </geometry>
    </visual>
  </link>
  <gazebo reference="adapter_1_2">
    <material>Gazebo/FlatBlack</material>
    <selfCollide>true</selfCollide>
  </gazebo>
  <!-- Contact Sensor -->
  <gazebo reference="adapter_1_2">
    <sensor name="adapter_1_2_contact_sensor" type="contact">
      <always_on>true</always_on>
      <contact>
        <collision>adapter_1_2_collision_collision</collision>
      </contact>
      <plugin filename="libgazebo_ros_bumper.so" name="adapter_1_2_plugin">
        <bumperTopicName>adapter_1_2_contact</bumperTopicName>
        <frameName>adapter_1_2</frameName>
      </plugin>
    </sensor>
  </gazebo>
  <!-- 1 Arm -->
  <link name="arm_1">
    <inertial>
      <origin rpy="0 0 0" xyz="0 0 0"/>
      <mass value="6"/>
      <inertia ixx="0.04875" ixy="0" ixz="0" iyy="0.04875" iyz="0" izz="0.00125"/>
    </inertial>
    <collision name="arm_1_collision">
      <geometry>
        <cylinder length="0.3" radius="0.05"/>
      </geometry>
    </collision>
    <visual>
      <geometry>
        <cylinder length="0.3" radius="0.05"/>
      </geometry>
    </visual>
  </link>
  <gazebo reference="arm_1">
    <material>Gazebo/DarkGrey</material>
    <selfCollide>true</selfCollide>
  </gazebo>
  <!-- 2 Adapter -->
  <link name="adapter_2_1">
    <inertial>
      <origin rpy="0 0 0" xyz="0 -0.003725 0.003727"/>
      <mass value="10"/>
      <inertia ixx="0.0172860847018" ixy="0" ixz="0" iyy="0.0172860847018" iyz="0" izz="0.0172860847018"/>
    </inertial>
    <collision name="adapter_2_1_collision">
      <geometry>
        <mesh filename="package://robot_desc/models/FirstLink.dae"/>
      </geometry>
    </collision>
    <visual>
      <geometry>
        <mesh filename="package://robot_desc/models/FirstLink.dae"/>
      </geometry>
    </visual>
  </link>
  <gazebo reference="adapter_2_1">
    <material>Gazebo/FlatBlack</material>
    <selfCollide>true</selfCollide>
  </gazebo>
  <!-- Contact Sensor -->
  <gazebo reference="adapter_2_1">
    <sensor name="adapter_2_1_contact_sensor" type="contact">
      <always_on>true</always_on>
      <contact>
        <collision>adapter_2_1_collision_collision</collision>
      </contact>
      <plugin filename="libgazebo_ros_bumper.so" name="adapter_2_1_plugin">
        <bumperTopicName>adapter_2_1_contact</bumperTopicName>
        <frameName>adapter_2_1</frameName>
      </plugin>
    </sensor>
  </gazebo>
  <link name="adapter_2_2">
    <inertial>
      <origin rpy="0 0 0" xyz="0 -0.003725 0.003727"/>
      <mass value="10"/>
      <inertia ixx="0.0172860847018" ixy="0" ixz="0" iyy="0.0172860847018" iyz="0" izz="0.0172860847018"/>
    </inertial>
    <collision name="adapter_2_2_collision">
      <geometry>
        <mesh filename="package://robot_desc/models/FirstLink.dae"/>
      </geometry>
    </collision>
    <visual>
      <geometry>
        <mesh filename="package://robot_desc/models/FirstLink.dae"/>
      </geometry>
    </visual>
  </link>
  <gazebo reference="adapter_2_2">
    <material>Gazebo/FlatBlack</material>
    <selfCollide>true</selfCollide>
  </gazebo>
  <!-- Contact Sensor -->
  <gazebo reference="adapter_2_2">
    <sensor name="adapter_2_2_contact_sensor" type="contact">
      <always_on>true</always_on>
      <contact>
        <collision>adapter_2_2_collision_collision</collision>
      </contact>
      <plugin filename="libgazebo_ros_bumper.so" name="adapter_2_2_plugin">
        <bumperTopicName>adapter_2_2_contact</bumperTopicName>
        <frameName>adapter_2_2</frameName>
      </plugin>
    </sensor>
  </gazebo>
  <!-- 1 Arm -->
  <link name="arm_2">
    <inertial>
      <origin rpy="0 0 0" xyz="0 0 0"/>
      <mass value="9"/>
      <inertia ixx="0.125625" ixy="0" ixz="0" iyy="0.125625" iyz="0" izz="0.001875"/>
    </inertial>
    <collision name="arm_2_collision">
      <geometry>
        <cylinder length="0.4" radius="0.05"/>
      </geometry>
    </collision>
    <visual>
      <geometry>
        <cylinder length="0.4" radius="0.05"/>
      </geometry>
    </visual>
  </link>
  <gazebo reference="arm_2">
    <material>Gazebo/DarkGrey</material>
    <selfCollide>true</selfCollide>
  </gazebo>
  <!-- 2 Adapter -->
  <link name="adapter_3_1">
    <inertial>
      <origin rpy="0 0 0" xyz="0 -0.003725 0.003727"/>
      <mass value="10"/>
      <inertia ixx="0.0172860847018" ixy="0" ixz="0" iyy="0.0172860847018" iyz="0" izz="0.0172860847018"/>
    </inertial>
    <collision name="adapter_3_1_collision">
      <geometry>
        <mesh filename="package://robot_desc/models/FirstLink.dae"/>
      </geometry>
    </collision>
    <visual>
      <geometry>
        <mesh filename="package://robot_desc/models/FirstLink.dae"/>
      </geometry>
    </visual>
  </link>
  <gazebo reference="adapter_3_1">
    <material>Gazebo/FlatBlack</material>
    <selfCollide>true</selfCollide>
  </gazebo>
  <!-- Contact Sensor -->
  <gazebo reference="adapter_3_1">
    <sensor name="adapter_3_1_contact_sensor" type="contact">
      <always_on>true</always_on>
      <contact>
        <collision>adapter_3_1_collision_collision</collision>
      </contact>
      <plugin filename="libgazebo_ros_bumper.so" name="adapter_3_1_plugin">
        <bumperTopicName>adapter_3_1_contact</bumperTopicName>
        <frameName>adapter_3_1</frameName>
      </plugin>
    </sensor>
  </gazebo>
  <link name="adapter_3_2">
    <inertial>
      <origin rpy="0 0 0" xyz="0 -0.003725 0.003727"/>
      <mass value="10"/>
      <inertia ixx="0.0172860847018" ixy="0" ixz="0" iyy="0.0172860847018" iyz="0" izz="0.0172860847018"/>
    </inertial>
    <collision name="adapter_3_2_collision">
      <geometry>
        <mesh filename="package://robot_desc/models/FirstLink.dae"/>
      </geometry>
    </collision>
    <visual>
      <geometry>
        <mesh filename="package://robot_desc/models/FirstLink.dae"/>
      </geometry>
    </visual>
  </link>
  <gazebo reference="adapter_3_2">
    <material>Gazebo/FlatBlack</material>
    <selfCollide>true</selfCollide>
  </gazebo>
  <!-- Contact Sensor -->
  <gazebo reference="adapter_3_2">
    <sensor name="adapter_3_2_contact_sensor" type="contact">
      <always_on>true</always_on>
      <contact>
        <collision>adapter_3_2_collision_collision</collision>
      </contact>
      <plugin filename="libgazebo_ros_bumper.so" name="adapter_3_2_plugin">
        <bumperTopicName>adapter_3_2_contact</bumperTopicName>
        <frameName>adapter_3_2</frameName>
      </plugin>
    </sensor>
  </gazebo>
  <!-- 1 Arm -->
  <link name="arm_3">
    <inertial>
      <origin rpy="0 0 0" xyz="0 0 0"/>
      <mass value="2"/>
      <inertia ixx="0.00291666666667" ixy="0" ixz="0" iyy="0.00291666666667" iyz="0" izz="0.000416666666667"/>
    </inertial>
    <collision name="arm_3_collision">
      <geometry>
        <cylinder length="0.1" radius="0.05"/>
      </geometry>
    </collision>
    <visual>
      <geometry>
        <cylinder length="0.1" radius="0.05"/>
      </geometry>
    </visual>
  </link>
  <gazebo reference="arm_3">
    <material>Gazebo/DarkGrey</material>
    <selfCollide>true</selfCollide>
  </gazebo>
  <!-- Tool Tip -->
  <link name="tooltip">
    <inertial>
      <origin rpy="0 0 0" xyz="0 0 0"/>
      <mass value="10"/>
      <inertia ixx="0.00633333333333" ixy="0" ixz="0" iyy="0.00633333333333" iyz="0" izz="0.00208333333333"/>
    </inertial>
    <collision>
      <geometry>
        <cylinder length="0.01" radius="0.05"/>
      </geometry>
    </collision>
    <visual>
      <geometry>
        <cylinder length="0.01" radius="0.05"/>
      </geometry>
    </visual>
  </link>
  <gazebo reference="tooltip">
    <material>Gazebo/DarkGrey</material>
    <selfCollide>true</selfCollide>
  </gazebo>
  <!-- EEF Dummy -->
  <link name="eef_dummy">
    <visual>
      <origin rpy="0 0 0" xyz="0 0 0"/>
      <geometry>
        <sphere radius="0.015"/>
      </geometry>
    </visual>
    <inertial>
      <origin rpy="0 0 0" xyz="0 0 0"/>
      <mass value="1"/>
      <inertia ixx="1.0" ixy="0.0" ixz="0.0" iyy="1.0" iyz="0.0" izz="1.0"/>
    </inertial>
  </link>
  <gazebo reference="eef_dummy">
    <material>Gazebo/Red</material>
  </gazebo>
  <joint name="eef_dummy_joint" type="fixed">
    <origin rpy="0 0 0" xyz="0 0 0.2"/>
    <parent link="tooltip"/>
    <child link="eef_dummy"/>
  </joint>
  <!-- Joint -->
  <joint name="base_model_adapter_1_1" type="revolute">
    <parent link="base_model"/>
    <child link="adapter_1_1"/>
    <origin rpy="0 3.14159265359 0" xyz="0 0 0.12"/>
    <axis xyz="0 0 1"/>
    <limit effort="1000.0" lower="-3.14159265359" upper="3.14159265359" velocity="3.2"/>
  </joint>
  <transmission name="base_model_adapter_1_1_trans">
    <type>transmission_interface/SimpleTransmission</type>
    <joint name="base_model_adapter_1_1">
      <hardwareInterface>hardware_interface/PositionJointInterface</hardwareInterface>
    </joint>
    <actuator name="base_model_adapter_1_1_motor">
      <mechanicalReduction>1</mechanicalReduction>
    </actuator>
  </transmission>
  <joint name="adapter_1_1_adapter_1_2" type="revolute">
    <parent link="adapter_1_1"/>
    <child link="adapter_1_2"/>
    <origin rpy="3.14159265359 0 0" xyz="0 -0.12 0"/>
    <axis xyz="0 1 0"/>
    <limit effort="1000.0" lower="-3.14159265359" upper="3.14159265359" velocity="3.2"/>
  </joint>
  <transmission name="adapter_1_1_adapter_1_2_trans">
    <type>transmission_interface/SimpleTransmission</type>
    <joint name="adapter_1_1_adapter_1_2">
      <hardwareInterface>hardware_interface/PositionJointInterface</hardwareInterface>
    </joint>
    <actuator name="adapter_1_1_adapter_1_2_motor">
      <mechanicalReduction>1</mechanicalReduction>
    </actuator>
  </transmission>
  <joint name="adapter_1_2_arm_1" type="fixed">
    <parent link="adapter_1_2"/>
    <child link="arm_1"/>
    <origin rpy="0 0 0" xyz="0 0 0.21"/>
  </joint>
  <joint name="arm_1_adapter_2_1" type="fixed">
    <parent link="arm_1"/>
    <child link="adapter_2_1"/>
    <origin rpy="1.57079632679 0 0" xyz="0 0 0.21"/>
  </joint>
  <joint name="adapter_2_1_adapter_2_2" type="revolute">
    <parent link="adapter_2_1"/>
    <child link="adapter_2_2"/>
    <origin rpy="3.14159265359 0 0" xyz="0 0 0.12"/>
    <axis xyz="0 0 1"/>
    <limit effort="1000.0" lower="-3.14159265359" upper="3.14159265359" velocity="3.2"/>
  </joint>
  <transmission name="adapter_2_1_adapter_2_2_trans">
    <type>transmission_interface/SimpleTransmission</type>
    <joint name="adapter_2_1_adapter_2_2">
      <hardwareInterface>hardware_interface/PositionJointInterface</hardwareInterface>
    </joint>
    <actuator name="adapter_2_1_adapter_2_2_motor">
      <mechanicalReduction>1</mechanicalReduction>
    </actuator>
  </transmission>
  <joint name="adapter_2_2_arm_2" type="fixed">
    <parent link="adapter_2_2"/>
    <child link="arm_2"/>
    <origin rpy="1.57079632679 0 0" xyz="0 -0.26 0"/>
  </joint>
  <joint name="arm_2_adapter_3_1" type="revolute">
    <parent link="arm_2"/>
    <child link="adapter_3_1"/>
    <origin rpy="3.14159265359 0 0" xyz="0 0 0.26"/>
    <axis xyz="0 0 1"/>
    <limit effort="1000.0" lower="-3.14159265359" upper="3.14159265359" velocity="3.2"/>
  </joint>
  <transmission name="arm_2_adapter_3_1_trans">
    <type>transmission_interface/SimpleTransmission</type>
    <joint name="arm_2_adapter_3_1">
      <hardwareInterface>hardware_interface/PositionJointInterface</hardwareInterface>
    </joint>
    <actuator name="arm_2_adapter_3_1_motor">
      <mechanicalReduction>1</mechanicalReduction>
    </actuator>
  </transmission>
  <joint name="adapter_3_1_adapter_3_2" type="revolute">
    <parent link="adapter_3_1"/>
    <child link="adapter_3_2"/>
    <origin rpy="3.14159265359 0 0" xyz="0 -0.12 0"/>
    <axis xyz="0 1 0"/>
    <limit effort="1000.0" lower="-3.14159265359" upper="3.14159265359" velocity="3.2"/>
  </joint>
  <transmission name="adapter_3_1_adapter_3_2_trans">
    <type>transmission_interface/SimpleTransmission</type>
    <joint name="adapter_3_1_adapter_3_2">
      <hardwareInterface>hardware_interface/PositionJointInterface</hardwareInterface>
    </joint>
    <actuator name="adapter_3_1_adapter_3_2_motor">
      <mechanicalReduction>1</mechanicalReduction>
    </actuator>
  </transmission>
  <joint name="adapter_3_2_arm_3" type="fixed">
    <parent link="adapter_3_2"/>
    <child link="arm_3"/>
    <origin rpy="0 0 0" xyz="0 0 0.11"/>
  </joint>
  <joint name="arm_3_tooltip" type="revolute">
    <parent link="arm_3"/>
    <child link="tooltip"/>
    <origin rpy="0 0 0" xyz="0 0 0.055"/>
    <axis xyz="0 0 1"/>
    <limit effort="1000.0" lower="-3.14159265359" upper="3.14159265359" velocity="3.2"/>
  </joint>
  <transmission name="arm_3_tooltip_trans">
    <type>transmission_interface/SimpleTransmission</type>
    <joint name="arm_3_tooltip">
      <hardwareInterface>hardware_interface/PositionJointInterface</hardwareInterface>
    </joint>
    <actuator name="arm_3_tooltip_motor">
      <mechanicalReduction>1</mechanicalReduction>
    </actuator>
  </transmission>
</robot>
