<?xml version="1.0" encoding="utf-8"?>
<!-- =================================================================================== -->
<!-- |    This document was autogenerated by xacro from /home/rizky/dev/catkin_ws/src/robot_desc/models/robot_environment.xacro | -->
<!-- |    EDITING THIS FILE BY HAND IS NOT RECOMMENDED                                 | -->
<!-- =================================================================================== -->
<robot name="armrobot">
  <gazebo>
    <plugin filename="libgazebo_ros_control.so" name="gazebo_ros_control">
    </plugin>
  </gazebo>
  <link name="world"/>
  <joint name="world_joint" type="fixed">
    <origin rpy="0 0 0" xyz="0 0 0"/>
    <parent link="world"/>
    <child link="base_model"/>
  </joint>
  <!-- Base Model -->
  <link name="base_model">
    <inertial>
      <origin rpy="0 0 0" xyz="2e-06 0 0.019926"/>
      <mass value="1000"/>
      <inertia ixx="4.811547714514836" ixy="0" ixz="0" iyy="4.811547714514836" iyz="0" izz="9.623095429029672"/>
    </inertial>
    <collision>
      <geometry>
        <mesh filename="package://robot_desc/models/BaseModel2.dae"/>
      </geometry>
    </collision>
    <visual>
      <geometry>
        <mesh filename="package://robot_desc/models/BaseModel2.dae"/>
      </geometry>
    </visual>
  </link>
  <gazebo reference="base_model">
    <material>Gazebo/DarkGrey</material>
    <selfCollide>true</selfCollide>
  </gazebo>
  <!-- Arm Construct -->
  <!-- 2 Adapter -->
  <link name="adapter_1_1">
    <inertial>
      <origin rpy="0 0 0" xyz="0 -0.003725 0.003727"/>
      <mass value="10"/>
      <inertia ixx="0.017286084701815037" ixy="0" ixz="0" iyy="0.017286084701815037" iyz="0" izz="0.017286084701815037"/>
    </inertial>
    <collision name="adapter_1_1_collision">
      <geometry>
        <mesh filename="package://robot_desc/models/FirstLink.dae"/>
      </geometry>
    </collision>
    <visual>
      <geometry>
        <mesh filename="package://robot_desc/models/FirstLink.dae"/>
      </geometry>
    </visual>
  </link>
  <gazebo reference="adapter_1_1">
    <material>Gazebo/FlatBlack</material>
    <selfCollide>true</selfCollide>
  </gazebo>
  <!-- Contact Sensor -->
  <gazebo reference="adapter_1_1">
    <sensor name="adapter_1_1_contact_sensor" type="contact">
      <always_on>true</always_on>
      <contact>
        <collision>adapter_1_1_collision_collision</collision>
      </contact>
      <plugin filename="libgazebo_ros_bumper.so" name="adapter_1_1_plugin">
        <bumperTopicName>adapter_1_1_contact</bumperTopicName>
        <frameName>adapter_1_1</frameName>
      </plugin>
    </sensor>
  </gazebo>
  <link name="adapter_1_2">
    <inertial>
      <origin rpy="0 0 0" xyz="0 -0.003725 0.003727"/>
      <mass value="10"/>
      <inertia ixx="0.017286084701815037" ixy="0" ixz="0" iyy="0.017286084701815037" iyz="0" izz="0.017286084701815037"/>
    </inertial>
    <collision name="adapter_1_2_collision">
      <geometry>
        <mesh filename="package://robot_desc/models/FirstLink.dae"/>
      </geometry>
    </collision>
    <visual>
      <geometry>
        <mesh filename="package://robot_desc/models/FirstLink.dae"/>
      </geometry>
    </visual>
  </link>
  <gazebo reference="adapter_1_2">
    <material>Gazebo/FlatBlack</material>
    <selfCollide>true</selfCollide>
  </gazebo>
  <!-- Contact Sensor -->
  <gazebo reference="adapter_1_2">
    <sensor name="adapter_1_2_contact_sensor" type="contact">
      <always_on>true</always_on>
      <contact>
        <collision>adapter_1_2_collision_collision</collision>
      </contact>
      <plugin filename="libgazebo_ros_bumper.so" name="adapter_1_2_plugin">
        <bumperTopicName>adapter_1_2_contact</bumperTopicName>
        <frameName>adapter_1_2</frameName>
      </plugin>
    </sensor>
  </gazebo>
  <!-- 1 Arm -->
  <link name="arm_1">
    <inertial>
      <origin rpy="0 0 0" xyz="0 0 0"/>
      <mass value="6"/>
      <inertia ixx="0.04875" ixy="0" ixz="0" iyy="0.04875" iyz="0" izz="0.0012500000000000002"/>
    </inertial>
    <collision name="arm_1_collision">
      <geometry>
        <cylinder length="0.3" radius="0.05"/>
      </geometry>
    </collision>
    <visual>
      <geometry>
        <cylinder length="0.3" radius="0.05"/>
      </geometry>
    </visual>
  </link>
  <gazebo reference="arm_1">
    <material>Gazebo/DarkGrey</material>
    <selfCollide>true</selfCollide>
  </gazebo>
  <!-- Contact Sensor -->
  <gazebo reference="arm_1">
    <sensor name="arm_1_contact_sensor" type="contact">
      <always_on>true</always_on>
      <contact>
        <collision>arm_1_collision_collision</collision>
      </contact>
      <plugin filename="libgazebo_ros_bumper.so" name="arm_1_plugin">
        <bumperTopicName>arm_1_contact</bumperTopicName>
        <frameName>arm_1</frameName>
      </plugin>
    </sensor>
  </gazebo>
  <!-- 2 Adapter -->
  <link name="adapter_2_1">
    <inertial>
      <origin rpy="0 0 0" xyz="0 -0.003725 0.003727"/>
      <mass value="10"/>
      <inertia ixx="0.017286084701815037" ixy="0" ixz="0" iyy="0.017286084701815037" iyz="0" izz="0.017286084701815037"/>
    </inertial>
    <collision name="adapter_2_1_collision">
      <geometry>
        <mesh filename="package://robot_desc/models/FirstLink.dae"/>
      </geometry>
    </collision>
    <visual>
      <geometry>
        <mesh filename="package://robot_desc/models/FirstLink.dae"/>
      </geometry>
    </visual>
  </link>
  <gazebo reference="adapter_2_1">
    <material>Gazebo/FlatBlack</material>
    <selfCollide>true</selfCollide>
  </gazebo>
  <!-- Contact Sensor -->
  <gazebo reference="adapter_2_1">
    <sensor name="adapter_2_1_contact_sensor" type="contact">
      <always_on>true</always_on>
      <contact>
        <collision>adapter_2_1_collision_collision</collision>
      </contact>
      <plugin filename="libgazebo_ros_bumper.so" name="adapter_2_1_plugin">
        <bumperTopicName>adapter_2_1_contact</bumperTopicName>
        <frameName>adapter_2_1</frameName>
      </plugin>
    </sensor>
  </gazebo>
  <link name="adapter_2_2">
    <inertial>
      <origin rpy="0 0 0" xyz="0 -0.003725 0.003727"/>
      <mass value="10"/>
      <inertia ixx="0.017286084701815037" ixy="0" ixz="0" iyy="0.017286084701815037" iyz="0" izz="0.017286084701815037"/>
    </inertial>
    <collision name="adapter_2_2_collision">
      <geometry>
        <mesh filename="package://robot_desc/models/FirstLink.dae"/>
      </geometry>
    </collision>
    <visual>
      <geometry>
        <mesh filename="package://robot_desc/models/FirstLink.dae"/>
      </geometry>
    </visual>
  </link>
  <gazebo reference="adapter_2_2">
    <material>Gazebo/FlatBlack</material>
    <selfCollide>true</selfCollide>
  </gazebo>
  <!-- Contact Sensor -->
  <gazebo reference="adapter_2_2">
    <sensor name="adapter_2_2_contact_sensor" type="contact">
      <always_on>true</always_on>
      <contact>
        <collision>adapter_2_2_collision_collision</collision>
      </contact>
      <plugin filename="libgazebo_ros_bumper.so" name="adapter_2_2_plugin">
        <bumperTopicName>adapter_2_2_contact</bumperTopicName>
        <frameName>adapter_2_2</frameName>
      </plugin>
    </sensor>
  </gazebo>
  <!-- 1 Arm -->
  <link name="arm_2">
    <inertial>
      <origin rpy="0 0 0" xyz="0 0 0"/>
      <mass value="9"/>
      <inertia ixx="0.12562500000000004" ixy="0" ixz="0" iyy="0.12562500000000004" iyz="0" izz="0.0018750000000000004"/>
    </inertial>
    <collision name="arm_2_collision">
      <geometry>
        <cylinder length="0.4" radius="0.05"/>
      </geometry>
    </collision>
    <visual>
      <geometry>
        <cylinder length="0.4" radius="0.05"/>
      </geometry>
    </visual>
  </link>
  <gazebo reference="arm_2">
    <material>Gazebo/DarkGrey</material>
    <selfCollide>true</selfCollide>
  </gazebo>
  <!-- Contact Sensor -->
  <gazebo reference="arm_2">
    <sensor name="arm_2_contact_sensor" type="contact">
      <always_on>true</always_on>
      <contact>
        <collision>arm_2_collision_collision</collision>
      </contact>
      <plugin filename="libgazebo_ros_bumper.so" name="arm_2_plugin">
        <bumperTopicName>arm_2_contact</bumperTopicName>
        <frameName>arm_2</frameName>
      </plugin>
    </sensor>
  </gazebo>
  <!-- 2 Adapter -->
  <link name="adapter_3_1">
    <inertial>
      <origin rpy="0 0 0" xyz="0 -0.003725 0.003727"/>
      <mass value="10"/>
      <inertia ixx="0.017286084701815037" ixy="0" ixz="0" iyy="0.017286084701815037" iyz="0" izz="0.017286084701815037"/>
    </inertial>
    <collision name="adapter_3_1_collision">
      <geometry>
        <mesh filename="package://robot_desc/models/FirstLink.dae"/>
      </geometry>
    </collision>
    <visual>
      <geometry>
        <mesh filename="package://robot_desc/models/FirstLink.dae"/>
      </geometry>
    </visual>
  </link>
  <gazebo reference="adapter_3_1">
    <material>Gazebo/FlatBlack</material>
    <selfCollide>true</selfCollide>
  </gazebo>
  <!-- Contact Sensor -->
  <gazebo reference="adapter_3_1">
    <sensor name="adapter_3_1_contact_sensor" type="contact">
      <always_on>true</always_on>
      <contact>
        <collision>adapter_3_1_collision_collision</collision>
      </contact>
      <plugin filename="libgazebo_ros_bumper.so" name="adapter_3_1_plugin">
        <bumperTopicName>adapter_3_1_contact</bumperTopicName>
        <frameName>adapter_3_1</frameName>
      </plugin>
    </sensor>
  </gazebo>
  <link name="adapter_3_2">
    <inertial>
      <origin rpy="0 0 0" xyz="0 -0.003725 0.003727"/>
      <mass value="10"/>
      <inertia ixx="0.017286084701815037" ixy="0" ixz="0" iyy="0.017286084701815037" iyz="0" izz="0.017286084701815037"/>
    </inertial>
    <collision name="adapter_3_2_collision">
      <geometry>
        <mesh filename="package://robot_desc/models/FirstLink.dae"/>
      </geometry>
    </collision>
    <visual>
      <geometry>
        <mesh filename="package://robot_desc/models/FirstLink.dae"/>
      </geometry>
    </visual>
  </link>
  <gazebo reference="adapter_3_2">
    <material>Gazebo/FlatBlack</material>
    <selfCollide>true</selfCollide>
  </gazebo>
  <!-- Contact Sensor -->
  <gazebo reference="adapter_3_2">
    <sensor name="adapter_3_2_contact_sensor" type="contact">
      <always_on>true</always_on>
      <contact>
        <collision>adapter_3_2_collision_collision</collision>
      </contact>
      <plugin filename="libgazebo_ros_bumper.so" name="adapter_3_2_plugin">
        <bumperTopicName>adapter_3_2_contact</bumperTopicName>
        <frameName>adapter_3_2</frameName>
      </plugin>
    </sensor>
  </gazebo>
  <!-- 1 Arm -->
  <link name="arm_3">
    <inertial>
      <origin rpy="0 0 0" xyz="0 0 0"/>
      <mass value="2"/>
      <inertia ixx="0.002916666666666667" ixy="0" ixz="0" iyy="0.002916666666666667" iyz="0" izz="0.00041666666666666675"/>
    </inertial>
    <collision name="arm_3_collision">
      <geometry>
        <cylinder length="0.1" radius="0.05"/>
      </geometry>
    </collision>
    <visual>
      <geometry>
        <cylinder length="0.1" radius="0.05"/>
      </geometry>
    </visual>
  </link>
  <gazebo reference="arm_3">
    <material>Gazebo/DarkGrey</material>
    <selfCollide>true</selfCollide>
  </gazebo>
  <!-- Contact Sensor -->
  <gazebo reference="arm_3">
    <sensor name="arm_3_contact_sensor" type="contact">
      <always_on>true</always_on>
      <contact>
        <collision>arm_3_collision_collision</collision>
      </contact>
      <plugin filename="libgazebo_ros_bumper.so" name="arm_3_plugin">
        <bumperTopicName>arm_3_contact</bumperTopicName>
        <frameName>arm_3</frameName>
      </plugin>
    </sensor>
  </gazebo>
  <!-- Tool Tip -->
  <link name="tooltip">
    <inertial>
      <origin rpy="0 0 0" xyz="0 0 0"/>
      <mass value="10"/>
      <inertia ixx="0.006333333333333334" ixy="0" ixz="0" iyy="0.006333333333333334" iyz="0" izz="0.0020833333333333337"/>
    </inertial>
    <collision>
      <geometry>
        <cylinder length="0.01" radius="0.05"/>
      </geometry>
    </collision>
    <visual>
      <geometry>
        <cylinder length="0.01" radius="0.05"/>
      </geometry>
    </visual>
  </link>
  <gazebo reference="tooltip">
    <material>Gazebo/DarkGrey</material>
    <selfCollide>true</selfCollide>
  </gazebo>
  <!-- EEF Dummy -->
  <link name="eef_dummy">
    <visual>
      <origin rpy="0 0 0" xyz="0 0 0"/>
      <geometry>
        <sphere radius="0.015"/>
      </geometry>
    </visual>
    <inertial>
      <origin rpy="0 0 0" xyz="0 0 0"/>
      <mass value="1"/>
      <inertia ixx="1.0" ixy="0.0" ixz="0.0" iyy="1.0" iyz="0.0" izz="1.0"/>
    </inertial>
  </link>
  <gazebo reference="eef_dummy">
    <material>Gazebo/Red</material>
  </gazebo>
  <joint name="eef_dummy_joint" type="fixed">
    <origin rpy="0 0 0" xyz="0 0 0.2"/>
    <parent link="tooltip"/>
    <child link="eef_dummy"/>
  </joint>
  <!-- Joint -->
  <joint name="base_model_adapter_1_1" type="revolute">
    <parent link="base_model"/>
    <child link="adapter_1_1"/>
    <origin rpy="0 3.141592653589793 0" xyz="0 0 0.12"/>
    <axis xyz="0 0 1"/>
    <limit effort="1000.0" lower="-3.141592653589793" upper="3.141592653589793" velocity="3.2"/>
  </joint>
  <transmission name="base_model_adapter_1_1_trans">
    <type>transmission_interface/SimpleTransmission</type>
    <joint name="base_model_adapter_1_1">
      <hardwareInterface>hardware_interface/PositionJointInterface</hardwareInterface>
    </joint>
    <actuator name="base_model_adapter_1_1_motor">
      <mechanicalReduction>1</mechanicalReduction>
    </actuator>
  </transmission>
  <joint name="adapter_1_1_adapter_1_2" type="revolute">
    <parent link="adapter_1_1"/>
    <child link="adapter_1_2"/>
    <origin rpy="3.141592653589793 0 0" xyz="0 -0.12 0"/>
    <axis xyz="0 1 0"/>
    <limit effort="1000.0" lower="-3.141592653589793" upper="3.141592653589793" velocity="3.2"/>
  </joint>
  <transmission name="adapter_1_1_adapter_1_2_trans">
    <type>transmission_interface/SimpleTransmission</type>
    <joint name="adapter_1_1_adapter_1_2">
      <hardwareInterface>hardware_interface/PositionJointInterface</hardwareInterface>
    </joint>
    <actuator name="adapter_1_1_adapter_1_2_motor">
      <mechanicalReduction>1</mechanicalReduction>
    </actuator>
  </transmission>
  <joint name="adapter_1_2_arm_1" type="revolute">
    <parent link="adapter_1_2"/>
    <child link="arm_1"/>
    <origin rpy="0 0 0" xyz="0 0 0.21"/>
    <axis xyz="0 0 1"/>
    <limit effort="1000.0" lower="0" upper="0" velocity="3.2"/>
  </joint>
  <transmission name="adapter_1_2_arm_1_trans">
    <type>transmission_interface/SimpleTransmission</type>
    <joint name="adapter_1_2_arm_1">
      <hardwareInterface>hardware_interface/PositionJointInterface</hardwareInterface>
    </joint>
    <actuator name="adapter_1_2_arm_1_motor">
      <mechanicalReduction>1</mechanicalReduction>
    </actuator>
  </transmission>
  <joint name="arm_1_adapter_2_1" type="revolute">
    <parent link="arm_1"/>
    <child link="adapter_2_1"/>
    <origin rpy="1.5707963267948966 0 0" xyz="0 0 0.21"/>
    <axis xyz="0 1 0"/>
    <limit effort="1000.0" lower="0" upper="0" velocity="3.2"/>
  </joint>
  <transmission name="arm_1_adapter_2_1_trans">
    <type>transmission_interface/SimpleTransmission</type>
    <joint name="arm_1_adapter_2_1">
      <hardwareInterface>hardware_interface/PositionJointInterface</hardwareInterface>
    </joint>
    <actuator name="arm_1_adapter_2_1_motor">
      <mechanicalReduction>1</mechanicalReduction>
    </actuator>
  </transmission>
  <joint name="adapter_2_1_adapter_2_2" type="revolute">
    <parent link="adapter_2_1"/>
    <child link="adapter_2_2"/>
    <origin rpy="3.141592653589793 0 0" xyz="0 0 0.12"/>
    <axis xyz="0 0 1"/>
    <limit effort="1000.0" lower="-3.141592653589793" upper="3.141592653589793" velocity="3.2"/>
  </joint>
  <transmission name="adapter_2_1_adapter_2_2_trans">
    <type>transmission_interface/SimpleTransmission</type>
    <joint name="adapter_2_1_adapter_2_2">
      <hardwareInterface>hardware_interface/PositionJointInterface</hardwareInterface>
    </joint>
    <actuator name="adapter_2_1_adapter_2_2_motor">
      <mechanicalReduction>1</mechanicalReduction>
    </actuator>
  </transmission>
  <joint name="adapter_2_2_arm_2" type="revolute">
    <parent link="adapter_2_2"/>
    <child link="arm_2"/>
    <origin rpy="1.5707963267948966 0 0" xyz="0 -0.26 0"/>
    <axis xyz="0 0 1"/>
    <limit effort="1000.0" lower="0" upper="0" velocity="3.2"/>
  </joint>
  <transmission name="adapter_2_2_arm_2_trans">
    <type>transmission_interface/SimpleTransmission</type>
    <joint name="adapter_2_2_arm_2">
      <hardwareInterface>hardware_interface/PositionJointInterface</hardwareInterface>
    </joint>
    <actuator name="adapter_2_2_arm_2_motor">
      <mechanicalReduction>1</mechanicalReduction>
    </actuator>
  </transmission>
  <joint name="arm_2_adapter_3_1" type="revolute">
    <parent link="arm_2"/>
    <child link="adapter_3_1"/>
    <origin rpy="3.141592653589793 0 0" xyz="0 0 0.26"/>
    <axis xyz="0 0 1"/>
    <limit effort="1000.0" lower="-3.141592653589793" upper="3.141592653589793" velocity="3.2"/>
  </joint>
  <transmission name="arm_2_adapter_3_1_trans">
    <type>transmission_interface/SimpleTransmission</type>
    <joint name="arm_2_adapter_3_1">
      <hardwareInterface>hardware_interface/PositionJointInterface</hardwareInterface>
    </joint>
    <actuator name="arm_2_adapter_3_1_motor">
      <mechanicalReduction>1</mechanicalReduction>
    </actuator>
  </transmission>
  <joint name="adapter_3_1_adapter_3_2" type="revolute">
    <parent link="adapter_3_1"/>
    <child link="adapter_3_2"/>
    <origin rpy="3.141592653589793 0 0" xyz="0 -0.12 0"/>
    <axis xyz="0 1 0"/>
    <limit effort="1000.0" lower="-3.141592653589793" upper="3.141592653589793" velocity="3.2"/>
  </joint>
  <transmission name="adapter_3_1_adapter_3_2_trans">
    <type>transmission_interface/SimpleTransmission</type>
    <joint name="adapter_3_1_adapter_3_2">
      <hardwareInterface>hardware_interface/PositionJointInterface</hardwareInterface>
    </joint>
    <actuator name="adapter_3_1_adapter_3_2_motor">
      <mechanicalReduction>1</mechanicalReduction>
    </actuator>
  </transmission>
  <joint name="adapter_3_2_arm_3" type="revolute">
    <parent link="adapter_3_2"/>
    <child link="arm_3"/>
    <origin rpy="0 0 0" xyz="0 0 0.11"/>
    <axis xyz="0 0 1"/>
    <limit effort="1000.0" lower="0" upper="0" velocity="3.2"/>
  </joint>
  <transmission name="adapter_3_2_arm_3_trans">
    <type>transmission_interface/SimpleTransmission</type>
    <joint name="adapter_3_2_arm_3">
      <hardwareInterface>hardware_interface/PositionJointInterface</hardwareInterface>
    </joint>
    <actuator name="adapter_3_2_arm_3_motor">
      <mechanicalReduction>1</mechanicalReduction>
    </actuator>
  </transmission>
  <joint name="arm_3_tooltip" type="revolute">
    <parent link="arm_3"/>
    <child link="tooltip"/>
    <origin rpy="0 0 0" xyz="0 0 0.055"/>
    <axis xyz="0 0 1"/>
    <limit effort="1000.0" lower="-3.141592653589793" upper="3.141592653589793" velocity="3.2"/>
  </joint>
  <transmission name="arm_3_tooltip_trans">
    <type>transmission_interface/SimpleTransmission</type>
    <joint name="arm_3_tooltip">
      <hardwareInterface>hardware_interface/PositionJointInterface</hardwareInterface>
    </joint>
    <actuator name="arm_3_tooltip_motor">
      <mechanicalReduction>1</mechanicalReduction>
    </actuator>
  </transmission>
</robot>
